2025-07-03 14:29:36,333 Worker rq:worker:2a7fced393294a179ec3eb2e5023fa7b: Redis connection timeout, quitting...
/home/jerono/bookbench/env/lib/python3.10/site-packages/rq/connections.py:58: DeprecationWarning: The `push_connection` function is deprecated. Pass the `connection` explicitly instead.
  warnings.warn(
/home/jerono/bookbench/env/lib/python3.10/site-packages/rq/connections.py:72: DeprecationWarning: The `pop_connection` function is deprecated. Pass the `connection` explicitly instead.
  warnings.warn(
/home/jerono/bookbench/env/lib/python3.10/site-packages/rq/connections.py:58: DeprecationWarning: The `push_connection` function is deprecated. Pass the `connection` explicitly instead.
  warnings.warn(
/home/jerono/bookbench/env/lib/python3.10/site-packages/rq/connections.py:72: DeprecationWarning: The `pop_connection` function is deprecated. Pass the `connection` explicitly instead.
  warnings.warn(
2025-07-03 14:41:52,638 Worker rq:worker:032c5e449dfe411680b6e525c2140a67: Redis connection timeout, quitting...
/home/jerono/bookbench/env/lib/python3.10/site-packages/rq/connections.py:58: DeprecationWarning: The `push_connection` function is deprecated. Pass the `connection` explicitly instead.
  warnings.warn(
/home/jerono/bookbench/env/lib/python3.10/site-packages/rq/connections.py:72: DeprecationWarning: The `pop_connection` function is deprecated. Pass the `connection` explicitly instead.
  warnings.warn(
2025-07-03 15:16:43,702 Worker rq:worker:191bacc2a12d400d882df2af597b10f6: Redis connection timeout, quitting...
2025-07-03 15:25:10,635 Worker rq:worker:d38173ae58ef4e4bbb996864d07514b8: Redis connection timeout, quitting...
2025-07-03 15:33:23,297 Worker rq:worker:4f2c8572fdd84b3a887b0be92046a302: Redis connection timeout, quitting...
/home/jerono/bookbench/env/lib/python3.10/site-packages/rq/connections.py:58: DeprecationWarning: The `push_connection` function is deprecated. Pass the `connection` explicitly instead.
  warnings.warn(
/home/jerono/bookbench/env/lib/python3.10/site-packages/rq/connections.py:72: DeprecationWarning: The `pop_connection` function is deprecated. Pass the `connection` explicitly instead.
  warnings.warn(
2025-07-03 15:46:42,163 Worker rq:worker:be3a91f28c8d40cbb465173aecb33ce7: Redis connection timeout, quitting...
Traceback (most recent call last):
  File "/home/jerono/bookbench/env/lib/python3.10/site-packages/redis/connection.py", line 699, in connect
    sock = self.retry.call_with_retry(
  File "/home/jerono/bookbench/env/lib/python3.10/site-packages/redis/retry.py", line 46, in call_with_retry
    return do()
  File "/home/jerono/bookbench/env/lib/python3.10/site-packages/redis/connection.py", line 700, in <lambda>
    lambda: self._connect(), lambda error: self.disconnect(error)
  File "/home/jerono/bookbench/env/lib/python3.10/site-packages/redis/connection.py", line 1002, in _connect
    raise err
  File "/home/jerono/bookbench/env/lib/python3.10/site-packages/redis/connection.py", line 990, in _connect
    sock.connect(socket_address)
ConnectionRefusedError: [Errno 111] Connection refused

During handling of the above exception, another exception occurred:

Traceback (most recent call last):
  File "/usr/lib/python3.10/runpy.py", line 196, in _run_module_as_main
    return _run_code(code, main_globals, None,
  File "/usr/lib/python3.10/runpy.py", line 86, in _run_code
    exec(code, run_globals)
  File "/home/jerono/bookbench/apps/frappe/frappe/utils/bench_helper.py", line 114, in <module>
    main()
  File "/home/jerono/bookbench/apps/frappe/frappe/utils/bench_helper.py", line 20, in main
    click.Group(commands=commands)(prog_name="bench")
  File "/home/jerono/bookbench/env/lib/python3.10/site-packages/click/core.py", line 1442, in __call__
    return self.main(*args, **kwargs)
  File "/home/jerono/bookbench/env/lib/python3.10/site-packages/click/core.py", line 1363, in main
    rv = self.invoke(ctx)
  File "/home/jerono/bookbench/env/lib/python3.10/site-packages/click/core.py", line 1830, in invoke
    return _process_result(sub_ctx.command.invoke(sub_ctx))
  File "/home/jerono/bookbench/env/lib/python3.10/site-packages/click/core.py", line 1830, in invoke
    return _process_result(sub_ctx.command.invoke(sub_ctx))
  File "/home/jerono/bookbench/env/lib/python3.10/site-packages/click/core.py", line 1226, in invoke
    return ctx.invoke(self.callback, **ctx.params)
  File "/home/jerono/bookbench/env/lib/python3.10/site-packages/click/core.py", line 794, in invoke
    return callback(*args, **kwargs)
  File "/home/jerono/bookbench/apps/frappe/frappe/commands/scheduler.py", line 205, in start_worker
    start_worker(
  File "/home/jerono/bookbench/apps/frappe/frappe/utils/background_jobs.py", line 305, in start_worker
    redis_connection = get_redis_conn(username=rq_username, password=rq_password)
  File "/home/jerono/bookbench/env/lib/python3.10/site-packages/tenacity/__init__.py", line 289, in wrapped_f
    return self(f, *args, **kw)
  File "/home/jerono/bookbench/env/lib/python3.10/site-packages/tenacity/__init__.py", line 379, in __call__
    do = self.iter(retry_state=retry_state)
  File "/home/jerono/bookbench/env/lib/python3.10/site-packages/tenacity/__init__.py", line 325, in iter
    raise retry_exc.reraise()
  File "/home/jerono/bookbench/env/lib/python3.10/site-packages/tenacity/__init__.py", line 158, in reraise
    raise self.last_attempt.result()
  File "/usr/lib/python3.10/concurrent/futures/_base.py", line 451, in result
    return self.__get_result()
  File "/usr/lib/python3.10/concurrent/futures/_base.py", line 403, in __get_result
    raise self._exception
  File "/home/jerono/bookbench/env/lib/python3.10/site-packages/tenacity/__init__.py", line 382, in __call__
    result = fn(*args, **kwargs)
  File "/home/jerono/bookbench/apps/frappe/frappe/utils/background_jobs.py", line 500, in get_redis_conn
    return get_redis_connection_without_auth()
  File "/home/jerono/bookbench/apps/frappe/frappe/utils/background_jobs.py", line 522, in get_redis_connection_without_auth
    _redis_queue_conn = RedisQueue.get_connection()
  File "/home/jerono/bookbench/apps/frappe/frappe/utils/redis_queue.py", line 35, in get_connection
    conn.ping()
  File "/home/jerono/bookbench/env/lib/python3.10/site-packages/redis/commands/core.py", line 1205, in ping
    return self.execute_command("PING", **kwargs)
  File "/home/jerono/bookbench/env/lib/python3.10/site-packages/redis/client.py", line 1266, in execute_command
    conn = self.connection or pool.get_connection(command_name, **options)
  File "/home/jerono/bookbench/env/lib/python3.10/site-packages/redis/connection.py", line 1457, in get_connection
    connection.connect()
  File "/home/jerono/bookbench/env/lib/python3.10/site-packages/redis/connection.py", line 705, in connect
    raise ConnectionError(self._error_message(e))
redis.exceptions.ConnectionError: Error 111 connecting to 127.0.0.1:11311. Connection refused.
Traceback (most recent call last):
  File "/home/jerono/bookbench/env/lib/python3.10/site-packages/redis/connection.py", line 699, in connect
    sock = self.retry.call_with_retry(
  File "/home/jerono/bookbench/env/lib/python3.10/site-packages/redis/retry.py", line 46, in call_with_retry
    return do()
  File "/home/jerono/bookbench/env/lib/python3.10/site-packages/redis/connection.py", line 700, in <lambda>
    lambda: self._connect(), lambda error: self.disconnect(error)
  File "/home/jerono/bookbench/env/lib/python3.10/site-packages/redis/connection.py", line 1002, in _connect
    raise err
  File "/home/jerono/bookbench/env/lib/python3.10/site-packages/redis/connection.py", line 990, in _connect
    sock.connect(socket_address)
ConnectionRefusedError: [Errno 111] Connection refused

During handling of the above exception, another exception occurred:

Traceback (most recent call last):
  File "/usr/lib/python3.10/runpy.py", line 196, in _run_module_as_main
    return _run_code(code, main_globals, None,
  File "/usr/lib/python3.10/runpy.py", line 86, in _run_code
    exec(code, run_globals)
  File "/home/jerono/bookbench/apps/frappe/frappe/utils/bench_helper.py", line 114, in <module>
    main()
  File "/home/jerono/bookbench/apps/frappe/frappe/utils/bench_helper.py", line 20, in main
    click.Group(commands=commands)(prog_name="bench")
  File "/home/jerono/bookbench/env/lib/python3.10/site-packages/click/core.py", line 1442, in __call__
    return self.main(*args, **kwargs)
  File "/home/jerono/bookbench/env/lib/python3.10/site-packages/click/core.py", line 1363, in main
    rv = self.invoke(ctx)
  File "/home/jerono/bookbench/env/lib/python3.10/site-packages/click/core.py", line 1830, in invoke
    return _process_result(sub_ctx.command.invoke(sub_ctx))
  File "/home/jerono/bookbench/env/lib/python3.10/site-packages/click/core.py", line 1830, in invoke
    return _process_result(sub_ctx.command.invoke(sub_ctx))
  File "/home/jerono/bookbench/env/lib/python3.10/site-packages/click/core.py", line 1226, in invoke
    return ctx.invoke(self.callback, **ctx.params)
  File "/home/jerono/bookbench/env/lib/python3.10/site-packages/click/core.py", line 794, in invoke
    return callback(*args, **kwargs)
  File "/home/jerono/bookbench/apps/frappe/frappe/commands/scheduler.py", line 205, in start_worker
    start_worker(
  File "/home/jerono/bookbench/apps/frappe/frappe/utils/background_jobs.py", line 305, in start_worker
    redis_connection = get_redis_conn(username=rq_username, password=rq_password)
  File "/home/jerono/bookbench/env/lib/python3.10/site-packages/tenacity/__init__.py", line 289, in wrapped_f
    return self(f, *args, **kw)
  File "/home/jerono/bookbench/env/lib/python3.10/site-packages/tenacity/__init__.py", line 379, in __call__
    do = self.iter(retry_state=retry_state)
  File "/home/jerono/bookbench/env/lib/python3.10/site-packages/tenacity/__init__.py", line 325, in iter
    raise retry_exc.reraise()
  File "/home/jerono/bookbench/env/lib/python3.10/site-packages/tenacity/__init__.py", line 158, in reraise
    raise self.last_attempt.result()
  File "/usr/lib/python3.10/concurrent/futures/_base.py", line 451, in result
    return self.__get_result()
  File "/usr/lib/python3.10/concurrent/futures/_base.py", line 403, in __get_result
    raise self._exception
  File "/home/jerono/bookbench/env/lib/python3.10/site-packages/tenacity/__init__.py", line 382, in __call__
    result = fn(*args, **kwargs)
  File "/home/jerono/bookbench/apps/frappe/frappe/utils/background_jobs.py", line 500, in get_redis_conn
    return get_redis_connection_without_auth()
  File "/home/jerono/bookbench/apps/frappe/frappe/utils/background_jobs.py", line 522, in get_redis_connection_without_auth
    _redis_queue_conn = RedisQueue.get_connection()
  File "/home/jerono/bookbench/apps/frappe/frappe/utils/redis_queue.py", line 35, in get_connection
    conn.ping()
  File "/home/jerono/bookbench/env/lib/python3.10/site-packages/redis/commands/core.py", line 1205, in ping
    return self.execute_command("PING", **kwargs)
  File "/home/jerono/bookbench/env/lib/python3.10/site-packages/redis/client.py", line 1266, in execute_command
    conn = self.connection or pool.get_connection(command_name, **options)
  File "/home/jerono/bookbench/env/lib/python3.10/site-packages/redis/connection.py", line 1457, in get_connection
    connection.connect()
  File "/home/jerono/bookbench/env/lib/python3.10/site-packages/redis/connection.py", line 705, in connect
    raise ConnectionError(self._error_message(e))
redis.exceptions.ConnectionError: Error 111 connecting to 127.0.0.1:11311. Connection refused.
Traceback (most recent call last):
  File "/home/jerono/bookbench/env/lib/python3.10/site-packages/redis/connection.py", line 699, in connect
    sock = self.retry.call_with_retry(
  File "/home/jerono/bookbench/env/lib/python3.10/site-packages/redis/retry.py", line 46, in call_with_retry
    return do()
  File "/home/jerono/bookbench/env/lib/python3.10/site-packages/redis/connection.py", line 700, in <lambda>
    lambda: self._connect(), lambda error: self.disconnect(error)
  File "/home/jerono/bookbench/env/lib/python3.10/site-packages/redis/connection.py", line 1002, in _connect
    raise err
  File "/home/jerono/bookbench/env/lib/python3.10/site-packages/redis/connection.py", line 990, in _connect
    sock.connect(socket_address)
ConnectionRefusedError: [Errno 111] Connection refused

During handling of the above exception, another exception occurred:

Traceback (most recent call last):
  File "/usr/lib/python3.10/runpy.py", line 196, in _run_module_as_main
    return _run_code(code, main_globals, None,
  File "/usr/lib/python3.10/runpy.py", line 86, in _run_code
    exec(code, run_globals)
  File "/home/jerono/bookbench/apps/frappe/frappe/utils/bench_helper.py", line 114, in <module>
    main()
  File "/home/jerono/bookbench/apps/frappe/frappe/utils/bench_helper.py", line 20, in main
    click.Group(commands=commands)(prog_name="bench")
  File "/home/jerono/bookbench/env/lib/python3.10/site-packages/click/core.py", line 1442, in __call__
    return self.main(*args, **kwargs)
  File "/home/jerono/bookbench/env/lib/python3.10/site-packages/click/core.py", line 1363, in main
    rv = self.invoke(ctx)
  File "/home/jerono/bookbench/env/lib/python3.10/site-packages/click/core.py", line 1830, in invoke
    return _process_result(sub_ctx.command.invoke(sub_ctx))
  File "/home/jerono/bookbench/env/lib/python3.10/site-packages/click/core.py", line 1830, in invoke
    return _process_result(sub_ctx.command.invoke(sub_ctx))
  File "/home/jerono/bookbench/env/lib/python3.10/site-packages/click/core.py", line 1226, in invoke
    return ctx.invoke(self.callback, **ctx.params)
  File "/home/jerono/bookbench/env/lib/python3.10/site-packages/click/core.py", line 794, in invoke
    return callback(*args, **kwargs)
  File "/home/jerono/bookbench/apps/frappe/frappe/commands/scheduler.py", line 205, in start_worker
    start_worker(
  File "/home/jerono/bookbench/apps/frappe/frappe/utils/background_jobs.py", line 305, in start_worker
    redis_connection = get_redis_conn(username=rq_username, password=rq_password)
  File "/home/jerono/bookbench/env/lib/python3.10/site-packages/tenacity/__init__.py", line 289, in wrapped_f
    return self(f, *args, **kw)
  File "/home/jerono/bookbench/env/lib/python3.10/site-packages/tenacity/__init__.py", line 379, in __call__
    do = self.iter(retry_state=retry_state)
  File "/home/jerono/bookbench/env/lib/python3.10/site-packages/tenacity/__init__.py", line 325, in iter
    raise retry_exc.reraise()
  File "/home/jerono/bookbench/env/lib/python3.10/site-packages/tenacity/__init__.py", line 158, in reraise
    raise self.last_attempt.result()
  File "/usr/lib/python3.10/concurrent/futures/_base.py", line 451, in result
    return self.__get_result()
  File "/usr/lib/python3.10/concurrent/futures/_base.py", line 403, in __get_result
    raise self._exception
  File "/home/jerono/bookbench/env/lib/python3.10/site-packages/tenacity/__init__.py", line 382, in __call__
    result = fn(*args, **kwargs)
  File "/home/jerono/bookbench/apps/frappe/frappe/utils/background_jobs.py", line 500, in get_redis_conn
    return get_redis_connection_without_auth()
  File "/home/jerono/bookbench/apps/frappe/frappe/utils/background_jobs.py", line 522, in get_redis_connection_without_auth
    _redis_queue_conn = RedisQueue.get_connection()
  File "/home/jerono/bookbench/apps/frappe/frappe/utils/redis_queue.py", line 35, in get_connection
    conn.ping()
  File "/home/jerono/bookbench/env/lib/python3.10/site-packages/redis/commands/core.py", line 1205, in ping
    return self.execute_command("PING", **kwargs)
  File "/home/jerono/bookbench/env/lib/python3.10/site-packages/redis/client.py", line 1266, in execute_command
    conn = self.connection or pool.get_connection(command_name, **options)
  File "/home/jerono/bookbench/env/lib/python3.10/site-packages/redis/connection.py", line 1457, in get_connection
    connection.connect()
  File "/home/jerono/bookbench/env/lib/python3.10/site-packages/redis/connection.py", line 705, in connect
    raise ConnectionError(self._error_message(e))
redis.exceptions.ConnectionError: Error 111 connecting to 127.0.0.1:11311. Connection refused.
Traceback (most recent call last):
  File "/home/jerono/bookbench/env/lib/python3.10/site-packages/redis/connection.py", line 699, in connect
    sock = self.retry.call_with_retry(
  File "/home/jerono/bookbench/env/lib/python3.10/site-packages/redis/retry.py", line 46, in call_with_retry
    return do()
  File "/home/jerono/bookbench/env/lib/python3.10/site-packages/redis/connection.py", line 700, in <lambda>
    lambda: self._connect(), lambda error: self.disconnect(error)
  File "/home/jerono/bookbench/env/lib/python3.10/site-packages/redis/connection.py", line 1002, in _connect
    raise err
  File "/home/jerono/bookbench/env/lib/python3.10/site-packages/redis/connection.py", line 990, in _connect
    sock.connect(socket_address)
ConnectionRefusedError: [Errno 111] Connection refused

During handling of the above exception, another exception occurred:

Traceback (most recent call last):
  File "/usr/lib/python3.10/runpy.py", line 196, in _run_module_as_main
    return _run_code(code, main_globals, None,
  File "/usr/lib/python3.10/runpy.py", line 86, in _run_code
    exec(code, run_globals)
  File "/home/jerono/bookbench/apps/frappe/frappe/utils/bench_helper.py", line 114, in <module>
    main()
  File "/home/jerono/bookbench/apps/frappe/frappe/utils/bench_helper.py", line 20, in main
    click.Group(commands=commands)(prog_name="bench")
  File "/home/jerono/bookbench/env/lib/python3.10/site-packages/click/core.py", line 1442, in __call__
    return self.main(*args, **kwargs)
  File "/home/jerono/bookbench/env/lib/python3.10/site-packages/click/core.py", line 1363, in main
    rv = self.invoke(ctx)
  File "/home/jerono/bookbench/env/lib/python3.10/site-packages/click/core.py", line 1830, in invoke
    return _process_result(sub_ctx.command.invoke(sub_ctx))
  File "/home/jerono/bookbench/env/lib/python3.10/site-packages/click/core.py", line 1830, in invoke
    return _process_result(sub_ctx.command.invoke(sub_ctx))
  File "/home/jerono/bookbench/env/lib/python3.10/site-packages/click/core.py", line 1226, in invoke
    return ctx.invoke(self.callback, **ctx.params)
  File "/home/jerono/bookbench/env/lib/python3.10/site-packages/click/core.py", line 794, in invoke
    return callback(*args, **kwargs)
  File "/home/jerono/bookbench/apps/frappe/frappe/commands/scheduler.py", line 205, in start_worker
    start_worker(
  File "/home/jerono/bookbench/apps/frappe/frappe/utils/background_jobs.py", line 305, in start_worker
    redis_connection = get_redis_conn(username=rq_username, password=rq_password)
  File "/home/jerono/bookbench/env/lib/python3.10/site-packages/tenacity/__init__.py", line 289, in wrapped_f
    return self(f, *args, **kw)
  File "/home/jerono/bookbench/env/lib/python3.10/site-packages/tenacity/__init__.py", line 379, in __call__
    do = self.iter(retry_state=retry_state)
  File "/home/jerono/bookbench/env/lib/python3.10/site-packages/tenacity/__init__.py", line 325, in iter
    raise retry_exc.reraise()
  File "/home/jerono/bookbench/env/lib/python3.10/site-packages/tenacity/__init__.py", line 158, in reraise
    raise self.last_attempt.result()
  File "/usr/lib/python3.10/concurrent/futures/_base.py", line 451, in result
    return self.__get_result()
  File "/usr/lib/python3.10/concurrent/futures/_base.py", line 403, in __get_result
    raise self._exception
  File "/home/jerono/bookbench/env/lib/python3.10/site-packages/tenacity/__init__.py", line 382, in __call__
    result = fn(*args, **kwargs)
  File "/home/jerono/bookbench/apps/frappe/frappe/utils/background_jobs.py", line 500, in get_redis_conn
    return get_redis_connection_without_auth()
  File "/home/jerono/bookbench/apps/frappe/frappe/utils/background_jobs.py", line 522, in get_redis_connection_without_auth
    _redis_queue_conn = RedisQueue.get_connection()
  File "/home/jerono/bookbench/apps/frappe/frappe/utils/redis_queue.py", line 35, in get_connection
    conn.ping()
  File "/home/jerono/bookbench/env/lib/python3.10/site-packages/redis/commands/core.py", line 1205, in ping
    return self.execute_command("PING", **kwargs)
  File "/home/jerono/bookbench/env/lib/python3.10/site-packages/redis/client.py", line 1266, in execute_command
    conn = self.connection or pool.get_connection(command_name, **options)
  File "/home/jerono/bookbench/env/lib/python3.10/site-packages/redis/connection.py", line 1457, in get_connection
    connection.connect()
  File "/home/jerono/bookbench/env/lib/python3.10/site-packages/redis/connection.py", line 705, in connect
    raise ConnectionError(self._error_message(e))
redis.exceptions.ConnectionError: Error 111 connecting to 127.0.0.1:11311. Connection refused.
Traceback (most recent call last):
  File "/home/jerono/bookbench/env/lib/python3.10/site-packages/redis/connection.py", line 699, in connect
    sock = self.retry.call_with_retry(
  File "/home/jerono/bookbench/env/lib/python3.10/site-packages/redis/retry.py", line 46, in call_with_retry
    return do()
  File "/home/jerono/bookbench/env/lib/python3.10/site-packages/redis/connection.py", line 700, in <lambda>
    lambda: self._connect(), lambda error: self.disconnect(error)
  File "/home/jerono/bookbench/env/lib/python3.10/site-packages/redis/connection.py", line 1002, in _connect
    raise err
  File "/home/jerono/bookbench/env/lib/python3.10/site-packages/redis/connection.py", line 990, in _connect
    sock.connect(socket_address)
ConnectionRefusedError: [Errno 111] Connection refused

During handling of the above exception, another exception occurred:

Traceback (most recent call last):
  File "/usr/lib/python3.10/runpy.py", line 196, in _run_module_as_main
    return _run_code(code, main_globals, None,
  File "/usr/lib/python3.10/runpy.py", line 86, in _run_code
    exec(code, run_globals)
  File "/home/jerono/bookbench/apps/frappe/frappe/utils/bench_helper.py", line 114, in <module>
    main()
  File "/home/jerono/bookbench/apps/frappe/frappe/utils/bench_helper.py", line 20, in main
    click.Group(commands=commands)(prog_name="bench")
  File "/home/jerono/bookbench/env/lib/python3.10/site-packages/click/core.py", line 1442, in __call__
    return self.main(*args, **kwargs)
  File "/home/jerono/bookbench/env/lib/python3.10/site-packages/click/core.py", line 1363, in main
    rv = self.invoke(ctx)
  File "/home/jerono/bookbench/env/lib/python3.10/site-packages/click/core.py", line 1830, in invoke
    return _process_result(sub_ctx.command.invoke(sub_ctx))
  File "/home/jerono/bookbench/env/lib/python3.10/site-packages/click/core.py", line 1830, in invoke
    return _process_result(sub_ctx.command.invoke(sub_ctx))
  File "/home/jerono/bookbench/env/lib/python3.10/site-packages/click/core.py", line 1226, in invoke
    return ctx.invoke(self.callback, **ctx.params)
  File "/home/jerono/bookbench/env/lib/python3.10/site-packages/click/core.py", line 794, in invoke
    return callback(*args, **kwargs)
  File "/home/jerono/bookbench/apps/frappe/frappe/commands/scheduler.py", line 205, in start_worker
    start_worker(
  File "/home/jerono/bookbench/apps/frappe/frappe/utils/background_jobs.py", line 305, in start_worker
    redis_connection = get_redis_conn(username=rq_username, password=rq_password)
  File "/home/jerono/bookbench/env/lib/python3.10/site-packages/tenacity/__init__.py", line 289, in wrapped_f
    return self(f, *args, **kw)
  File "/home/jerono/bookbench/env/lib/python3.10/site-packages/tenacity/__init__.py", line 379, in __call__
    do = self.iter(retry_state=retry_state)
  File "/home/jerono/bookbench/env/lib/python3.10/site-packages/tenacity/__init__.py", line 325, in iter
    raise retry_exc.reraise()
  File "/home/jerono/bookbench/env/lib/python3.10/site-packages/tenacity/__init__.py", line 158, in reraise
    raise self.last_attempt.result()
  File "/usr/lib/python3.10/concurrent/futures/_base.py", line 451, in result
    return self.__get_result()
  File "/usr/lib/python3.10/concurrent/futures/_base.py", line 403, in __get_result
    raise self._exception
  File "/home/jerono/bookbench/env/lib/python3.10/site-packages/tenacity/__init__.py", line 382, in __call__
    result = fn(*args, **kwargs)
  File "/home/jerono/bookbench/apps/frappe/frappe/utils/background_jobs.py", line 500, in get_redis_conn
    return get_redis_connection_without_auth()
  File "/home/jerono/bookbench/apps/frappe/frappe/utils/background_jobs.py", line 522, in get_redis_connection_without_auth
    _redis_queue_conn = RedisQueue.get_connection()
  File "/home/jerono/bookbench/apps/frappe/frappe/utils/redis_queue.py", line 35, in get_connection
    conn.ping()
  File "/home/jerono/bookbench/env/lib/python3.10/site-packages/redis/commands/core.py", line 1205, in ping
    return self.execute_command("PING", **kwargs)
  File "/home/jerono/bookbench/env/lib/python3.10/site-packages/redis/client.py", line 1266, in execute_command
    conn = self.connection or pool.get_connection(command_name, **options)
  File "/home/jerono/bookbench/env/lib/python3.10/site-packages/redis/connection.py", line 1457, in get_connection
    connection.connect()
  File "/home/jerono/bookbench/env/lib/python3.10/site-packages/redis/connection.py", line 705, in connect
    raise ConnectionError(self._error_message(e))
redis.exceptions.ConnectionError: Error 111 connecting to 127.0.0.1:11311. Connection refused.
Traceback (most recent call last):
  File "/home/jerono/bookbench/env/lib/python3.10/site-packages/redis/connection.py", line 699, in connect
    sock = self.retry.call_with_retry(
  File "/home/jerono/bookbench/env/lib/python3.10/site-packages/redis/retry.py", line 46, in call_with_retry
    return do()
  File "/home/jerono/bookbench/env/lib/python3.10/site-packages/redis/connection.py", line 700, in <lambda>
    lambda: self._connect(), lambda error: self.disconnect(error)
  File "/home/jerono/bookbench/env/lib/python3.10/site-packages/redis/connection.py", line 1002, in _connect
    raise err
  File "/home/jerono/bookbench/env/lib/python3.10/site-packages/redis/connection.py", line 990, in _connect
    sock.connect(socket_address)
ConnectionRefusedError: [Errno 111] Connection refused

During handling of the above exception, another exception occurred:

Traceback (most recent call last):
  File "/usr/lib/python3.10/runpy.py", line 196, in _run_module_as_main
    return _run_code(code, main_globals, None,
  File "/usr/lib/python3.10/runpy.py", line 86, in _run_code
    exec(code, run_globals)
  File "/home/jerono/bookbench/apps/frappe/frappe/utils/bench_helper.py", line 114, in <module>
    main()
  File "/home/jerono/bookbench/apps/frappe/frappe/utils/bench_helper.py", line 20, in main
    click.Group(commands=commands)(prog_name="bench")
  File "/home/jerono/bookbench/env/lib/python3.10/site-packages/click/core.py", line 1442, in __call__
    return self.main(*args, **kwargs)
  File "/home/jerono/bookbench/env/lib/python3.10/site-packages/click/core.py", line 1363, in main
    rv = self.invoke(ctx)
  File "/home/jerono/bookbench/env/lib/python3.10/site-packages/click/core.py", line 1830, in invoke
    return _process_result(sub_ctx.command.invoke(sub_ctx))
  File "/home/jerono/bookbench/env/lib/python3.10/site-packages/click/core.py", line 1830, in invoke
    return _process_result(sub_ctx.command.invoke(sub_ctx))
  File "/home/jerono/bookbench/env/lib/python3.10/site-packages/click/core.py", line 1226, in invoke
    return ctx.invoke(self.callback, **ctx.params)
  File "/home/jerono/bookbench/env/lib/python3.10/site-packages/click/core.py", line 794, in invoke
    return callback(*args, **kwargs)
  File "/home/jerono/bookbench/apps/frappe/frappe/commands/scheduler.py", line 205, in start_worker
    start_worker(
  File "/home/jerono/bookbench/apps/frappe/frappe/utils/background_jobs.py", line 305, in start_worker
    redis_connection = get_redis_conn(username=rq_username, password=rq_password)
  File "/home/jerono/bookbench/env/lib/python3.10/site-packages/tenacity/__init__.py", line 289, in wrapped_f
    return self(f, *args, **kw)
  File "/home/jerono/bookbench/env/lib/python3.10/site-packages/tenacity/__init__.py", line 379, in __call__
    do = self.iter(retry_state=retry_state)
  File "/home/jerono/bookbench/env/lib/python3.10/site-packages/tenacity/__init__.py", line 325, in iter
    raise retry_exc.reraise()
  File "/home/jerono/bookbench/env/lib/python3.10/site-packages/tenacity/__init__.py", line 158, in reraise
    raise self.last_attempt.result()
  File "/usr/lib/python3.10/concurrent/futures/_base.py", line 451, in result
    return self.__get_result()
  File "/usr/lib/python3.10/concurrent/futures/_base.py", line 403, in __get_result
    raise self._exception
  File "/home/jerono/bookbench/env/lib/python3.10/site-packages/tenacity/__init__.py", line 382, in __call__
    result = fn(*args, **kwargs)
  File "/home/jerono/bookbench/apps/frappe/frappe/utils/background_jobs.py", line 500, in get_redis_conn
    return get_redis_connection_without_auth()
  File "/home/jerono/bookbench/apps/frappe/frappe/utils/background_jobs.py", line 522, in get_redis_connection_without_auth
    _redis_queue_conn = RedisQueue.get_connection()
  File "/home/jerono/bookbench/apps/frappe/frappe/utils/redis_queue.py", line 35, in get_connection
    conn.ping()
  File "/home/jerono/bookbench/env/lib/python3.10/site-packages/redis/commands/core.py", line 1205, in ping
    return self.execute_command("PING", **kwargs)
  File "/home/jerono/bookbench/env/lib/python3.10/site-packages/redis/client.py", line 1266, in execute_command
    conn = self.connection or pool.get_connection(command_name, **options)
  File "/home/jerono/bookbench/env/lib/python3.10/site-packages/redis/connection.py", line 1457, in get_connection
    connection.connect()
  File "/home/jerono/bookbench/env/lib/python3.10/site-packages/redis/connection.py", line 705, in connect
    raise ConnectionError(self._error_message(e))
redis.exceptions.ConnectionError: Error 111 connecting to 127.0.0.1:11311. Connection refused.
Traceback (most recent call last):
  File "/home/jerono/bookbench/env/lib/python3.10/site-packages/redis/connection.py", line 699, in connect
    sock = self.retry.call_with_retry(
  File "/home/jerono/bookbench/env/lib/python3.10/site-packages/redis/retry.py", line 46, in call_with_retry
    return do()
  File "/home/jerono/bookbench/env/lib/python3.10/site-packages/redis/connection.py", line 700, in <lambda>
    lambda: self._connect(), lambda error: self.disconnect(error)
  File "/home/jerono/bookbench/env/lib/python3.10/site-packages/redis/connection.py", line 1002, in _connect
    raise err
  File "/home/jerono/bookbench/env/lib/python3.10/site-packages/redis/connection.py", line 990, in _connect
    sock.connect(socket_address)
ConnectionRefusedError: [Errno 111] Connection refused

During handling of the above exception, another exception occurred:

Traceback (most recent call last):
  File "/usr/lib/python3.10/runpy.py", line 196, in _run_module_as_main
    return _run_code(code, main_globals, None,
  File "/usr/lib/python3.10/runpy.py", line 86, in _run_code
    exec(code, run_globals)
  File "/home/jerono/bookbench/apps/frappe/frappe/utils/bench_helper.py", line 114, in <module>
    main()
  File "/home/jerono/bookbench/apps/frappe/frappe/utils/bench_helper.py", line 20, in main
    click.Group(commands=commands)(prog_name="bench")
  File "/home/jerono/bookbench/env/lib/python3.10/site-packages/click/core.py", line 1442, in __call__
    return self.main(*args, **kwargs)
  File "/home/jerono/bookbench/env/lib/python3.10/site-packages/click/core.py", line 1363, in main
    rv = self.invoke(ctx)
  File "/home/jerono/bookbench/env/lib/python3.10/site-packages/click/core.py", line 1830, in invoke
    return _process_result(sub_ctx.command.invoke(sub_ctx))
  File "/home/jerono/bookbench/env/lib/python3.10/site-packages/click/core.py", line 1830, in invoke
    return _process_result(sub_ctx.command.invoke(sub_ctx))
  File "/home/jerono/bookbench/env/lib/python3.10/site-packages/click/core.py", line 1226, in invoke
    return ctx.invoke(self.callback, **ctx.params)
  File "/home/jerono/bookbench/env/lib/python3.10/site-packages/click/core.py", line 794, in invoke
    return callback(*args, **kwargs)
  File "/home/jerono/bookbench/apps/frappe/frappe/commands/scheduler.py", line 205, in start_worker
    start_worker(
  File "/home/jerono/bookbench/apps/frappe/frappe/utils/background_jobs.py", line 305, in start_worker
    redis_connection = get_redis_conn(username=rq_username, password=rq_password)
  File "/home/jerono/bookbench/env/lib/python3.10/site-packages/tenacity/__init__.py", line 289, in wrapped_f
    return self(f, *args, **kw)
  File "/home/jerono/bookbench/env/lib/python3.10/site-packages/tenacity/__init__.py", line 379, in __call__
    do = self.iter(retry_state=retry_state)
  File "/home/jerono/bookbench/env/lib/python3.10/site-packages/tenacity/__init__.py", line 325, in iter
    raise retry_exc.reraise()
  File "/home/jerono/bookbench/env/lib/python3.10/site-packages/tenacity/__init__.py", line 158, in reraise
    raise self.last_attempt.result()
  File "/usr/lib/python3.10/concurrent/futures/_base.py", line 451, in result
    return self.__get_result()
  File "/usr/lib/python3.10/concurrent/futures/_base.py", line 403, in __get_result
    raise self._exception
  File "/home/jerono/bookbench/env/lib/python3.10/site-packages/tenacity/__init__.py", line 382, in __call__
    result = fn(*args, **kwargs)
  File "/home/jerono/bookbench/apps/frappe/frappe/utils/background_jobs.py", line 500, in get_redis_conn
    return get_redis_connection_without_auth()
  File "/home/jerono/bookbench/apps/frappe/frappe/utils/background_jobs.py", line 522, in get_redis_connection_without_auth
    _redis_queue_conn = RedisQueue.get_connection()
  File "/home/jerono/bookbench/apps/frappe/frappe/utils/redis_queue.py", line 35, in get_connection
    conn.ping()
  File "/home/jerono/bookbench/env/lib/python3.10/site-packages/redis/commands/core.py", line 1205, in ping
    return self.execute_command("PING", **kwargs)
  File "/home/jerono/bookbench/env/lib/python3.10/site-packages/redis/client.py", line 1266, in execute_command
    conn = self.connection or pool.get_connection(command_name, **options)
  File "/home/jerono/bookbench/env/lib/python3.10/site-packages/redis/connection.py", line 1457, in get_connection
    connection.connect()
  File "/home/jerono/bookbench/env/lib/python3.10/site-packages/redis/connection.py", line 705, in connect
    raise ConnectionError(self._error_message(e))
redis.exceptions.ConnectionError: Error 111 connecting to 127.0.0.1:11311. Connection refused.
Exception in thread Thread-1:
Traceback (most recent call last):
  File "/usr/lib/python3.10/threading.py", line 1016, in _bootstrap_inner
    self.run()
  File "/home/jerono/bookbench/env/lib/python3.10/site-packages/redis/client.py", line 1799, in run
    pubsub.get_message(ignore_subscribe_messages=True, timeout=sleep_time)
  File "/home/jerono/bookbench/env/lib/python3.10/site-packages/redis/client.py", line 1690, in get_message
    response = self.parse_response(block=(timeout is None), timeout=timeout)
  File "/home/jerono/bookbench/env/lib/python3.10/site-packages/redis/client.py", line 1542, in parse_response
    response = self._execute(conn, try_read)
  File "/home/jerono/bookbench/env/lib/python3.10/site-packages/redis/client.py", line 1518, in _execute
    return conn.retry.call_with_retry(
  File "/home/jerono/bookbench/env/lib/python3.10/site-packages/redis/retry.py", line 49, in call_with_retry
    fail(error)
  File "/home/jerono/bookbench/env/lib/python3.10/site-packages/redis/client.py", line 1520, in <lambda>
    lambda error: self._disconnect_raise_connect(conn, error),
  File "/home/jerono/bookbench/env/lib/python3.10/site-packages/redis/client.py", line 1507, in _disconnect_raise_connect
    raise error
  File "/home/jerono/bookbench/env/lib/python3.10/site-packages/redis/retry.py", line 46, in call_with_retry
    return do()
  File "/home/jerono/bookbench/env/lib/python3.10/site-packages/redis/client.py", line 1519, in <lambda>
    lambda: command(*args, **kwargs),
  File "/home/jerono/bookbench/env/lib/python3.10/site-packages/redis/client.py", line 1536, in try_read
    if not conn.can_read(timeout=timeout):
  File "/home/jerono/bookbench/env/lib/python3.10/site-packages/redis/connection.py", line 861, in can_read
    return self._parser.can_read(timeout)
  File "/home/jerono/bookbench/env/lib/python3.10/site-packages/redis/connection.py", line 444, in can_read
    return self.read_from_socket(timeout=timeout, raise_on_timeout=False)
  File "/home/jerono/bookbench/env/lib/python3.10/site-packages/redis/connection.py", line 455, in read_from_socket
    raise ConnectionError(SERVER_CLOSED_CONNECTION_ERROR)
redis.exceptions.ConnectionError: Connection closed by server.
Traceback (most recent call last):
  File "/home/jerono/bookbench/env/lib/python3.10/site-packages/redis/connection.py", line 699, in connect
    sock = self.retry.call_with_retry(
  File "/home/jerono/bookbench/env/lib/python3.10/site-packages/redis/retry.py", line 46, in call_with_retry
    return do()
  File "/home/jerono/bookbench/env/lib/python3.10/site-packages/redis/connection.py", line 700, in <lambda>
    lambda: self._connect(), lambda error: self.disconnect(error)
  File "/home/jerono/bookbench/env/lib/python3.10/site-packages/redis/connection.py", line 1002, in _connect
    raise err
  File "/home/jerono/bookbench/env/lib/python3.10/site-packages/redis/connection.py", line 990, in _connect
    sock.connect(socket_address)
ConnectionRefusedError: [Errno 111] Connection refused

During handling of the above exception, another exception occurred:

Traceback (most recent call last):
  File "/usr/lib/python3.10/runpy.py", line 196, in _run_module_as_main
    return _run_code(code, main_globals, None,
  File "/usr/lib/python3.10/runpy.py", line 86, in _run_code
    exec(code, run_globals)
  File "/home/jerono/bookbench/apps/frappe/frappe/utils/bench_helper.py", line 114, in <module>
    main()
  File "/home/jerono/bookbench/apps/frappe/frappe/utils/bench_helper.py", line 20, in main
    click.Group(commands=commands)(prog_name="bench")
  File "/home/jerono/bookbench/env/lib/python3.10/site-packages/click/core.py", line 1442, in __call__
    return self.main(*args, **kwargs)
  File "/home/jerono/bookbench/env/lib/python3.10/site-packages/click/core.py", line 1363, in main
    rv = self.invoke(ctx)
  File "/home/jerono/bookbench/env/lib/python3.10/site-packages/click/core.py", line 1830, in invoke
    return _process_result(sub_ctx.command.invoke(sub_ctx))
  File "/home/jerono/bookbench/env/lib/python3.10/site-packages/click/core.py", line 1830, in invoke
    return _process_result(sub_ctx.command.invoke(sub_ctx))
  File "/home/jerono/bookbench/env/lib/python3.10/site-packages/click/core.py", line 1226, in invoke
    return ctx.invoke(self.callback, **ctx.params)
  File "/home/jerono/bookbench/env/lib/python3.10/site-packages/click/core.py", line 794, in invoke
    return callback(*args, **kwargs)
  File "/home/jerono/bookbench/apps/frappe/frappe/commands/scheduler.py", line 205, in start_worker
    start_worker(
  File "/home/jerono/bookbench/apps/frappe/frappe/utils/background_jobs.py", line 321, in start_worker
    worker.work(
  File "/home/jerono/bookbench/env/lib/python3.10/site-packages/rq/worker.py", line 456, in work
    self.teardown()
  File "/home/jerono/bookbench/env/lib/python3.10/site-packages/rq/worker.py", line 1047, in teardown
    self.unsubscribe()
  File "/home/jerono/bookbench/env/lib/python3.10/site-packages/rq/worker.py", line 624, in unsubscribe
    self.pubsub.unsubscribe()
  File "/home/jerono/bookbench/env/lib/python3.10/site-packages/redis/client.py", line 1659, in unsubscribe
    return self.execute_command("UNSUBSCRIBE", *args)
  File "/home/jerono/bookbench/env/lib/python3.10/site-packages/redis/client.py", line 1479, in execute_command
    self._execute(connection, connection.send_command, *args, **kwargs)
  File "/home/jerono/bookbench/env/lib/python3.10/site-packages/redis/client.py", line 1518, in _execute
    return conn.retry.call_with_retry(
  File "/home/jerono/bookbench/env/lib/python3.10/site-packages/redis/retry.py", line 49, in call_with_retry
    fail(error)
  File "/home/jerono/bookbench/env/lib/python3.10/site-packages/redis/client.py", line 1520, in <lambda>
    lambda error: self._disconnect_raise_connect(conn, error),
  File "/home/jerono/bookbench/env/lib/python3.10/site-packages/redis/client.py", line 1507, in _disconnect_raise_connect
    raise error
  File "/home/jerono/bookbench/env/lib/python3.10/site-packages/redis/retry.py", line 46, in call_with_retry
    return do()
  File "/home/jerono/bookbench/env/lib/python3.10/site-packages/redis/client.py", line 1519, in <lambda>
    lambda: command(*args, **kwargs),
  File "/home/jerono/bookbench/env/lib/python3.10/site-packages/redis/connection.py", line 847, in send_command
    self.send_packed_command(
  File "/home/jerono/bookbench/env/lib/python3.10/site-packages/redis/connection.py", line 817, in send_packed_command
    self.connect()
  File "/home/jerono/bookbench/env/lib/python3.10/site-packages/redis/connection.py", line 705, in connect
    raise ConnectionError(self._error_message(e))
redis.exceptions.ConnectionError: Error 111 connecting to localhost:11000. Connection refused.
Exception in thread Thread-1:
Traceback (most recent call last):
  File "/usr/lib/python3.10/threading.py", line 1016, in _bootstrap_inner
    self.run()
  File "/home/jerono/bookbench/env/lib/python3.10/site-packages/redis/client.py", line 1799, in run
    pubsub.get_message(ignore_subscribe_messages=True, timeout=sleep_time)
  File "/home/jerono/bookbench/env/lib/python3.10/site-packages/redis/client.py", line 1690, in get_message
    response = self.parse_response(block=(timeout is None), timeout=timeout)
  File "/home/jerono/bookbench/env/lib/python3.10/site-packages/redis/client.py", line 1542, in parse_response
    response = self._execute(conn, try_read)
  File "/home/jerono/bookbench/env/lib/python3.10/site-packages/redis/client.py", line 1518, in _execute
    return conn.retry.call_with_retry(
  File "/home/jerono/bookbench/env/lib/python3.10/site-packages/redis/retry.py", line 49, in call_with_retry
    fail(error)
  File "/home/jerono/bookbench/env/lib/python3.10/site-packages/redis/client.py", line 1520, in <lambda>
    lambda error: self._disconnect_raise_connect(conn, error),
  File "/home/jerono/bookbench/env/lib/python3.10/site-packages/redis/client.py", line 1507, in _disconnect_raise_connect
    raise error
  File "/home/jerono/bookbench/env/lib/python3.10/site-packages/redis/retry.py", line 46, in call_with_retry
    return do()
  File "/home/jerono/bookbench/env/lib/python3.10/site-packages/redis/client.py", line 1519, in <lambda>
    lambda: command(*args, **kwargs),
  File "/home/jerono/bookbench/env/lib/python3.10/site-packages/redis/client.py", line 1536, in try_read
    if not conn.can_read(timeout=timeout):
  File "/home/jerono/bookbench/env/lib/python3.10/site-packages/redis/connection.py", line 861, in can_read
    return self._parser.can_read(timeout)
  File "/home/jerono/bookbench/env/lib/python3.10/site-packages/redis/connection.py", line 444, in can_read
    return self.read_from_socket(timeout=timeout, raise_on_timeout=False)
  File "/home/jerono/bookbench/env/lib/python3.10/site-packages/redis/connection.py", line 455, in read_from_socket
    raise ConnectionError(SERVER_CLOSED_CONNECTION_ERROR)
redis.exceptions.ConnectionError: Connection closed by server.
Traceback (most recent call last):
  File "/home/jerono/bookbench/env/lib/python3.10/site-packages/redis/connection.py", line 699, in connect
    sock = self.retry.call_with_retry(
  File "/home/jerono/bookbench/env/lib/python3.10/site-packages/redis/retry.py", line 46, in call_with_retry
    return do()
  File "/home/jerono/bookbench/env/lib/python3.10/site-packages/redis/connection.py", line 700, in <lambda>
    lambda: self._connect(), lambda error: self.disconnect(error)
  File "/home/jerono/bookbench/env/lib/python3.10/site-packages/redis/connection.py", line 1002, in _connect
    raise err
  File "/home/jerono/bookbench/env/lib/python3.10/site-packages/redis/connection.py", line 990, in _connect
    sock.connect(socket_address)
ConnectionRefusedError: [Errno 111] Connection refused

During handling of the above exception, another exception occurred:

Traceback (most recent call last):
  File "/usr/lib/python3.10/runpy.py", line 196, in _run_module_as_main
    return _run_code(code, main_globals, None,
  File "/usr/lib/python3.10/runpy.py", line 86, in _run_code
    exec(code, run_globals)
  File "/home/jerono/bookbench/apps/frappe/frappe/utils/bench_helper.py", line 114, in <module>
    main()
  File "/home/jerono/bookbench/apps/frappe/frappe/utils/bench_helper.py", line 20, in main
    click.Group(commands=commands)(prog_name="bench")
  File "/home/jerono/bookbench/env/lib/python3.10/site-packages/click/core.py", line 1442, in __call__
    return self.main(*args, **kwargs)
  File "/home/jerono/bookbench/env/lib/python3.10/site-packages/click/core.py", line 1363, in main
    rv = self.invoke(ctx)
  File "/home/jerono/bookbench/env/lib/python3.10/site-packages/click/core.py", line 1830, in invoke
    return _process_result(sub_ctx.command.invoke(sub_ctx))
  File "/home/jerono/bookbench/env/lib/python3.10/site-packages/click/core.py", line 1830, in invoke
    return _process_result(sub_ctx.command.invoke(sub_ctx))
  File "/home/jerono/bookbench/env/lib/python3.10/site-packages/click/core.py", line 1226, in invoke
    return ctx.invoke(self.callback, **ctx.params)
  File "/home/jerono/bookbench/env/lib/python3.10/site-packages/click/core.py", line 794, in invoke
    return callback(*args, **kwargs)
  File "/home/jerono/bookbench/apps/frappe/frappe/commands/scheduler.py", line 205, in start_worker
    start_worker(
  File "/home/jerono/bookbench/apps/frappe/frappe/utils/background_jobs.py", line 321, in start_worker
    worker.work(
  File "/home/jerono/bookbench/env/lib/python3.10/site-packages/rq/worker.py", line 456, in work
    self.teardown()
  File "/home/jerono/bookbench/env/lib/python3.10/site-packages/rq/worker.py", line 1047, in teardown
    self.unsubscribe()
  File "/home/jerono/bookbench/env/lib/python3.10/site-packages/rq/worker.py", line 624, in unsubscribe
    self.pubsub.unsubscribe()
  File "/home/jerono/bookbench/env/lib/python3.10/site-packages/redis/client.py", line 1659, in unsubscribe
    return self.execute_command("UNSUBSCRIBE", *args)
  File "/home/jerono/bookbench/env/lib/python3.10/site-packages/redis/client.py", line 1479, in execute_command
    self._execute(connection, connection.send_command, *args, **kwargs)
  File "/home/jerono/bookbench/env/lib/python3.10/site-packages/redis/client.py", line 1518, in _execute
    return conn.retry.call_with_retry(
  File "/home/jerono/bookbench/env/lib/python3.10/site-packages/redis/retry.py", line 49, in call_with_retry
    fail(error)
  File "/home/jerono/bookbench/env/lib/python3.10/site-packages/redis/client.py", line 1520, in <lambda>
    lambda error: self._disconnect_raise_connect(conn, error),
  File "/home/jerono/bookbench/env/lib/python3.10/site-packages/redis/client.py", line 1507, in _disconnect_raise_connect
    raise error
  File "/home/jerono/bookbench/env/lib/python3.10/site-packages/redis/retry.py", line 46, in call_with_retry
    return do()
  File "/home/jerono/bookbench/env/lib/python3.10/site-packages/redis/client.py", line 1519, in <lambda>
    lambda: command(*args, **kwargs),
  File "/home/jerono/bookbench/env/lib/python3.10/site-packages/redis/connection.py", line 847, in send_command
    self.send_packed_command(
  File "/home/jerono/bookbench/env/lib/python3.10/site-packages/redis/connection.py", line 817, in send_packed_command
    self.connect()
  File "/home/jerono/bookbench/env/lib/python3.10/site-packages/redis/connection.py", line 705, in connect
    raise ConnectionError(self._error_message(e))
redis.exceptions.ConnectionError: Error 111 connecting to localhost:11000. Connection refused.
Exception in thread Thread-1:
Traceback (most recent call last):
  File "/usr/lib/python3.10/threading.py", line 1016, in _bootstrap_inner
    self.run()
  File "/home/jerono/bookbench/env/lib/python3.10/site-packages/redis/client.py", line 1799, in run
    pubsub.get_message(ignore_subscribe_messages=True, timeout=sleep_time)
  File "/home/jerono/bookbench/env/lib/python3.10/site-packages/redis/client.py", line 1690, in get_message
    response = self.parse_response(block=(timeout is None), timeout=timeout)
  File "/home/jerono/bookbench/env/lib/python3.10/site-packages/redis/client.py", line 1542, in parse_response
    response = self._execute(conn, try_read)
  File "/home/jerono/bookbench/env/lib/python3.10/site-packages/redis/client.py", line 1518, in _execute
    return conn.retry.call_with_retry(
  File "/home/jerono/bookbench/env/lib/python3.10/site-packages/redis/retry.py", line 49, in call_with_retry
    fail(error)
  File "/home/jerono/bookbench/env/lib/python3.10/site-packages/redis/client.py", line 1520, in <lambda>
    lambda error: self._disconnect_raise_connect(conn, error),
  File "/home/jerono/bookbench/env/lib/python3.10/site-packages/redis/client.py", line 1507, in _disconnect_raise_connect
    raise error
  File "/home/jerono/bookbench/env/lib/python3.10/site-packages/redis/retry.py", line 46, in call_with_retry
    return do()
  File "/home/jerono/bookbench/env/lib/python3.10/site-packages/redis/client.py", line 1519, in <lambda>
    lambda: command(*args, **kwargs),
  File "/home/jerono/bookbench/env/lib/python3.10/site-packages/redis/client.py", line 1536, in try_read
    if not conn.can_read(timeout=timeout):
  File "/home/jerono/bookbench/env/lib/python3.10/site-packages/redis/connection.py", line 861, in can_read
    return self._parser.can_read(timeout)
  File "/home/jerono/bookbench/env/lib/python3.10/site-packages/redis/connection.py", line 444, in can_read
    return self.read_from_socket(timeout=timeout, raise_on_timeout=False)
  File "/home/jerono/bookbench/env/lib/python3.10/site-packages/redis/connection.py", line 455, in read_from_socket
    raise ConnectionError(SERVER_CLOSED_CONNECTION_ERROR)
redis.exceptions.ConnectionError: Connection closed by server.
Traceback (most recent call last):
  File "/home/jerono/bookbench/env/lib/python3.10/site-packages/redis/connection.py", line 699, in connect
    sock = self.retry.call_with_retry(
  File "/home/jerono/bookbench/env/lib/python3.10/site-packages/redis/retry.py", line 46, in call_with_retry
    return do()
  File "/home/jerono/bookbench/env/lib/python3.10/site-packages/redis/connection.py", line 700, in <lambda>
    lambda: self._connect(), lambda error: self.disconnect(error)
  File "/home/jerono/bookbench/env/lib/python3.10/site-packages/redis/connection.py", line 1002, in _connect
    raise err
  File "/home/jerono/bookbench/env/lib/python3.10/site-packages/redis/connection.py", line 990, in _connect
    sock.connect(socket_address)
ConnectionRefusedError: [Errno 111] Connection refused

During handling of the above exception, another exception occurred:

Traceback (most recent call last):
  File "/usr/lib/python3.10/runpy.py", line 196, in _run_module_as_main
    return _run_code(code, main_globals, None,
  File "/usr/lib/python3.10/runpy.py", line 86, in _run_code
    exec(code, run_globals)
  File "/home/jerono/bookbench/apps/frappe/frappe/utils/bench_helper.py", line 114, in <module>
    main()
  File "/home/jerono/bookbench/apps/frappe/frappe/utils/bench_helper.py", line 20, in main
    click.Group(commands=commands)(prog_name="bench")
  File "/home/jerono/bookbench/env/lib/python3.10/site-packages/click/core.py", line 1442, in __call__
    return self.main(*args, **kwargs)
  File "/home/jerono/bookbench/env/lib/python3.10/site-packages/click/core.py", line 1363, in main
    rv = self.invoke(ctx)
  File "/home/jerono/bookbench/env/lib/python3.10/site-packages/click/core.py", line 1830, in invoke
    return _process_result(sub_ctx.command.invoke(sub_ctx))
  File "/home/jerono/bookbench/env/lib/python3.10/site-packages/click/core.py", line 1830, in invoke
    return _process_result(sub_ctx.command.invoke(sub_ctx))
  File "/home/jerono/bookbench/env/lib/python3.10/site-packages/click/core.py", line 1226, in invoke
    return ctx.invoke(self.callback, **ctx.params)
  File "/home/jerono/bookbench/env/lib/python3.10/site-packages/click/core.py", line 794, in invoke
    return callback(*args, **kwargs)
  File "/home/jerono/bookbench/apps/frappe/frappe/commands/scheduler.py", line 205, in start_worker
    start_worker(
  File "/home/jerono/bookbench/apps/frappe/frappe/utils/background_jobs.py", line 321, in start_worker
    worker.work(
  File "/home/jerono/bookbench/env/lib/python3.10/site-packages/rq/worker.py", line 456, in work
    self.teardown()
  File "/home/jerono/bookbench/env/lib/python3.10/site-packages/rq/worker.py", line 1047, in teardown
    self.unsubscribe()
  File "/home/jerono/bookbench/env/lib/python3.10/site-packages/rq/worker.py", line 624, in unsubscribe
    self.pubsub.unsubscribe()
  File "/home/jerono/bookbench/env/lib/python3.10/site-packages/redis/client.py", line 1659, in unsubscribe
    return self.execute_command("UNSUBSCRIBE", *args)
  File "/home/jerono/bookbench/env/lib/python3.10/site-packages/redis/client.py", line 1479, in execute_command
    self._execute(connection, connection.send_command, *args, **kwargs)
  File "/home/jerono/bookbench/env/lib/python3.10/site-packages/redis/client.py", line 1518, in _execute
    return conn.retry.call_with_retry(
  File "/home/jerono/bookbench/env/lib/python3.10/site-packages/redis/retry.py", line 49, in call_with_retry
    fail(error)
  File "/home/jerono/bookbench/env/lib/python3.10/site-packages/redis/client.py", line 1520, in <lambda>
    lambda error: self._disconnect_raise_connect(conn, error),
  File "/home/jerono/bookbench/env/lib/python3.10/site-packages/redis/client.py", line 1507, in _disconnect_raise_connect
    raise error
  File "/home/jerono/bookbench/env/lib/python3.10/site-packages/redis/retry.py", line 46, in call_with_retry
    return do()
  File "/home/jerono/bookbench/env/lib/python3.10/site-packages/redis/client.py", line 1519, in <lambda>
    lambda: command(*args, **kwargs),
  File "/home/jerono/bookbench/env/lib/python3.10/site-packages/redis/connection.py", line 847, in send_command
    self.send_packed_command(
  File "/home/jerono/bookbench/env/lib/python3.10/site-packages/redis/connection.py", line 817, in send_packed_command
    self.connect()
  File "/home/jerono/bookbench/env/lib/python3.10/site-packages/redis/connection.py", line 705, in connect
    raise ConnectionError(self._error_message(e))
redis.exceptions.ConnectionError: Error 111 connecting to localhost:11000. Connection refused.
/home/jerono/bookbench/env/lib/python3.10/site-packages/rq/connections.py:58: DeprecationWarning: The `push_connection` function is deprecated. Pass the `connection` explicitly instead.
  warnings.warn(
/home/jerono/bookbench/env/lib/python3.10/site-packages/rq/connections.py:72: DeprecationWarning: The `pop_connection` function is deprecated. Pass the `connection` explicitly instead.
  warnings.warn(
/home/jerono/bookbench/env/lib/python3.10/site-packages/rq/connections.py:58: DeprecationWarning: The `push_connection` function is deprecated. Pass the `connection` explicitly instead.
  warnings.warn(
/home/jerono/bookbench/env/lib/python3.10/site-packages/rq/connections.py:72: DeprecationWarning: The `pop_connection` function is deprecated. Pass the `connection` explicitly instead.
  warnings.warn(
